Workbook
Name ACT_QTR_00_01: #REF!
Name ACT_QTR_00_01: #REF!

Sheet PT_IMPORT_VALRS_H
E3: Petroleum Planning & Analysis Cell
A5: Period : 1998-99 - 2022-23
A6: ('Rs. Crore)
A7: Import/Export of Crude oil and Petroleum Products
A8: IMPORT/EXPORT | B8: 1998-99 | C8: 1999-2000 | D8: 2000-01 | E8: 2001-02 | F8: 2002-03 | G8: 2003-04 | H8: 2004-05 | I8: 2005-06 | J8: 2006-07 | K8: 2007-08 | L8: 2008-09 | M8: 2009-10 | N8: 2010-11 | O8: 2011-12 | P8: 2012-13 | Q8: 2013-14 | R8: 2014-15 | S8: 2015-16 | T8: =+'PT_Import_Val_2016-17 '!C5 -> 2016-17 | U8: ='PT_Import_Val_2017-18'!C5 -> 2017-18 | V8: 2018-19 | W8: 2019-20 | X8: 2020-21 | Y8: 2021-22 | Z8: 2022-23
A9: IMPORT^
A10: CRUDE OIL$ | B10: 14917 | C10: 40028 | D10: 65932 | E10: 60397 | F10: 76195 | G10: 83528 | H10: 117003 | I10: 171702 | J10: 219029 | K10: 272699 | L10: 348304 | M10: 375277 | N10: 455276.3 | O10: =+'PT_IMPORT_VALRS_H 2011-12'!N11 -> 672219.84 | P10: =+'PT_IMPORT_VALRS_H 2012-13 '!N11 -> 784652.28 | Q10: =+'PT_IMPORT_VALRS_H_2013-14'!N11 -> 864874.78 | R10: =+'PT_IMPORT_VALRS_H_2014-15'!N11 -> 687416.17 | S10: =+'PT_IMPORT_VALRS_H_2015-16'!N11 -> 416578.84 | T10: =+'PT_Import_Val_2016-17 '!P10 -> 470159.32 | U10: ='PT_Import_Val_2017-18'!P10 -> 566450.15 | V10: ='PT_Import_Val_2018-19'!N11 -> 783182.85 | W10: ='PT_Import_Val_2019-20'!N11 -> 717000.98 | X10: ='PT_Import_Val_2020-21'!N11 -> 459778.57 | Y10: ='PT_Import_Val_2021-22'!N11 -> 901262.19 | Z10: ='PT_Import_Val_2022-23'!N11 -> 1260371.8
A11: PRODUCT
A12: LPG | B12: 1273 | C12: 1801 | D12: 1332 | E12: 810 | F12: 1867 | G12: 2558 | H12: 4413 | I12: 7042 | J12: 5766 | K12: 8700 | L12: 8072 | M12: 8328.8218 | N12: 15888.161 | O12: =+'PT_IMPORT_VALRS_H 2011-12'!N13 -> 27018.53 | P12: =+'PT_IMPORT_VALRS_H 2012-13 '!N13 -> 31674.188 | Q12: =+'PT_IMPORT_VALRS_H_2013-14'!N13 -> 37213.088 | R12: =+'PT_IMPORT_VALRS_H_2014-15'!N13 -> 36570.547 | S12: =+'PT_IMPORT_VALRS_H_2015-16'!N13 -> 25777.839 | T12: =+'PT_Import_Val_2016-17 '!P12 -> 32124.419 | U12: ='PT_Import_Val_2017-18'!P12 -> 37875.197 | V12: ='PT_Import_Val_2018-19'!N13 -> 49939.043 | W12: ='PT_Import_Val_2019-20'!N13 -> 50347.453 | X12: ='PT_Import_Val_2020-21'!N13 -> 53752.459 | Y12: ='PT_Import_Val_2021-22'!N13 -> 91468.398 | Z12: ='PT_Import_Val_2022-23'!N13 -> 107191.17
A13: MS | B13: 191 | C13: 0 | D13: 0 | E13: 0 | F13: 0 | G13: 0 | H13: 501 | I13: 1286 | J13: 1326 | K13: 1137 | L13: 1553 | M13: 1264.0711 | N13: 6426.604 | O13: =+'PT_IMPORT_VALRS_H 2011-12'!N14 -> 3311.4823 | P13: =+'PT_IMPORT_VALRS_H 2012-13 '!N14 -> 890.51099 | Q13: =+'PT_IMPORT_VALRS_H_2013-14'!N14 -> 1481.0118 | R13: =+'PT_IMPORT_VALRS_H_2014-15'!N14 -> 2301.1519 | S13: =+'PT_IMPORT_VALRS_H_2015-16'!N14 -> 4207.4428 | T13: =+'PT_Import_Val_2016-17 '!P13 -> 1617.1461 | U13: ='PT_Import_Val_2017-18'!P13 -> 581.49809 | V13: ='PT_Import_Val_2018-19'!N14 -> 3103.9306 | W13: ='PT_Import_Val_2019-20'!N14 -> 9610.0367 | X13: ='PT_Import_Val_2020-21'!N14 -> 4949.6252 | Y13: ='PT_Import_Val_2021-22'!N14 -> 3894.803 | Z13: ='PT_Import_Val_2022-23'!N14 -> 8846.4554
A14: Naphtha | B14: 1336 | C14: 1965 | D14: 4106 | E14: 3477 | F14: 3551 | G14: 2884 | H14: 4029 | I14: 5400 | J14: 14277 | K14: 18470 | L14: 17409 | M14: 4942.2384 | N14: 6852.984 | O14: =+'PT_IMPORT_VALRS_H 2011-12'!N15 -> 9827.4364 | P14: =+'PT_IMPORT_VALRS_H 2012-13 '!N15 -> 9272.1133 | Q14: =+'PT_IMPORT_VALRS_H_2013-14'!N15 -> 6044.0835 | R14: =+'PT_IMPORT_VALRS_H_2014-15'!N15 -> 4592.0392 | S14: =+'PT_IMPORT_VALRS_H_2015-16'!N15 -> 9580.6031 | T14: =+'PT_Import_Val_2016-17 '!P14 -> 8373.9485 | U14: ='PT_Import_Val_2017-18'!P14 -> 8161.2125 | V14: ='PT_Import_Val_2018-19'!N15 -> 9665.3772 | W14: ='PT_Import_Val_2019-20'!N15 -> 6677.7277 | X14: ='PT_Import_Val_2020-21'!N15 -> 3844.0436 | Y14: ='PT_Import_Val_2021-22'!N15 -> 1498.7955 | Z14: ='PT_Import_Val_2022-23'!N15 -> 4781.3313
A15: ATF | B15: 0 | C15: 0 | D15: 0 | E15: 0 | F15: 0 | G15: 0 | H15: 0 | I15: 0 | J15: 0 | K15: 0 | L15: 0 | N15: 0 | O15: 0 | P15: 0 | Q15: 0 | R15: =+'PT_IMPORT_VALRS_H_2014-15'!N16 -> 706.08128 | S15: =+'PT_IMPORT_VALRS_H_2015-16'!N16 -> 888.80449 | T15: =+'PT_Import_Val_2016-17 '!P15 -> 1108.9512 | U15: ='PT_Import_Val_2017-18'!P15 -> 1159.3122 | V15: ='PT_Import_Val_2018-19'!N16 -> 1392.4629 | W15: ='PT_Import_Val_2019-20'!N16 -> 308.65469 | X15: ='PT_Import_Val_2020-21'!N16 -> 0.0086963 | Y15: ='PT_Import_Val_2021-22'!N16 -> 0 | Z15: ='PT_Import_Val_2022-23'!N16 -> 0.0013425
A16: SKO | B16: 3912 | C16: 5544 | D16: 2386 | E16: 388 | F16: 808 | G16: 890 | H16: 429 | I16: 2617 | J16: 4250 | K16: 8324 | L16: 6583 | M16: 2908.8127 | N16: 4939.415 | O16: =+'PT_IMPORT_VALRS_H 2011-12'!N17 -> 2710.3582 | P16: =+'PT_IMPORT_VALRS_H 2012-13 '!N17 -> 0 | Q16: =+'PT_IMPORT_VALRS_H_2013-14'!N17 -> 0 | R16: =+'PT_IMPORT_VALRS_H_2014-15'!N17 -> 171.71028 | S16: =+'PT_IMPORT_VALRS_H_2015-16'!N17 -> 158.12073 | T16: =+'PT_Import_Val_2016-17 '!P16 -> 0 | U16: ='PT_Import_Val_2017-18'!P16 -> 0 | V16: ='PT_Import_Val_2018-19'!N17 -> 0 | W16: ='PT_Import_Val_2019-20'!N17 -> 0 | X16: ='PT_Import_Val_2020-21'!N17 -> 12.137498 | Y16: ='PT_Import_Val_2021-22'!N17 -> 0 | Z16: ='PT_Import_Val_2022-23'!N17 -> 0
A17: HSD | B17: 4808 | C17: 3713 | D17: 0 | E17: 28 | F17: 119 | G17: 116 | H17: 1604 | I17: 1902 | J17: 2670 | K17: 9212 | L17: 9774 | M17: 6389.7336 | N17: 6969.0024 | O17: =+'PT_IMPORT_VALRS_H 2011-12'!N18 -> 5039.2569 | P17: =+'PT_IMPORT_VALRS_H 2012-13 '!N18 -> 2770.9472 | Q17: =+'PT_IMPORT_VALRS_H_2013-14'!N18 -> 451.67562 | R17: =+'PT_IMPORT_VALRS_H_2014-15'!N18 -> 669.54916 | S17: =+'PT_IMPORT_VALRS_H_2015-16'!N18 -> 605.19438 | T17: =+'PT_Import_Val_2016-17 '!P17 -> 2958.8357 | U17: ='PT_Import_Val_2017-18'!P17 -> 4268.7572 | V17: ='PT_Import_Val_2018-19'!N18 -> 2485.7659 | W17: ='PT_Import_Val_2019-20'!N18 -> 11619.049 | X17: ='PT_Import_Val_2020-21'!N18 -> 1960.043 | Y17: ='PT_Import_Val_2021-22'!N18 -> 252.98604 | Z17: ='PT_Import_Val_2022-23'!N18 -> 3584.0415
A18: LOBS/ Lube oil | B18: 148 | C18: 294 | D18: 563 | E18: 588 | F18: 526 | G18: 982 | H18: 963 | I18: 2945 | J18: 3392 | K18: 3402 | L18: 4552 | M18: 3518.1888 | N18: 4093.3356 | O18: =+'PT_IMPORT_VALRS_H 2011-12'!N19 -> 8313.6318 | P18: =+'PT_IMPORT_VALRS_H 2012-13 '!N19 -> 11339.253 | Q18: =+'PT_IMPORT_VALRS_H_2013-14'!N19 -> 12984.519 | R18: =+'PT_IMPORT_VALRS_H_2014-15'!N19 -> 12701.527 | S18: =+'PT_IMPORT_VALRS_H_2015-16'!N19 -> 9477.6807 | T18: =+'PT_Import_Val_2016-17 '!P18 -> 8625.2845 | U18: ='PT_Import_Val_2017-18'!P18 -> 12074.64 | V18: ='PT_Import_Val_2018-19'!N19 -> 13349.247 | W18: ='PT_Import_Val_2019-20'!N19 -> 11868.744 | X18: ='PT_Import_Val_2020-21'!N19 -> 12170.253 | Y18: ='PT_Import_Val_2021-22'!N19 -> 19704.254 | Z18: ='PT_Import_Val_2022-23'!N19 -> 18449.368
A19: Fuel Oil | B19: 602 | C19: 865 | D19: 1309 | E19: 1466 | F19: 1959 | G19: 1550 | H19: 1704 | I19: 2999 | J19: 5174 | K19: 7485 | L19: 7729 | M19: 1935.4663 | N19: 2455.3674 | O19: =+'PT_IMPORT_VALRS_H 2011-12'!N20 -> 4392.1028 | P19: =+'PT_IMPORT_VALRS_H 2012-13 '!N20 -> 4217.73 | Q19: =+'PT_IMPORT_VALRS_H_2013-14'!N20 -> 5758.6986 | R19: =+'PT_IMPORT_VALRS_H_2014-15'!N20 -> 3658.9311 | S19: =+'PT_IMPORT_VALRS_H_2015-16'!N20 -> 2379.6118 | T19: =+'PT_Import_Val_2016-17 '!P19 -> 1847.7016 | U19: ='PT_Import_Val_2017-18'!P19 -> 3231.4544 | V19: ='PT_Import_Val_2018-19'!N20 -> 4781.8737 | W19: ='PT_Import_Val_2019-20'!N20 -> 11791.441 | X19: ='PT_Import_Val_2020-21'!N20 -> 14311.684 | Y19: ='PT_Import_Val_2021-22'!N20 -> 32814.782 | Z19: ='PT_Import_Val_2022-23'!N20 -> 33474.246
A20: Bitumen | B20: 0 | C20: 0 | D20: 0 | E20: 5 | F20: 0 | G20: 5 | H20: 17 | I20: 22 | J20: 19 | K20: 50 | L20: 207 | M20: 137.73758 | N20: 209.50424 | O20: =+'PT_IMPORT_VALRS_H 2011-12'!N21 -> 196.7816 | P20: =+'PT_IMPORT_VALRS_H 2012-13 '!N21 -> 272.11671 | Q20: =+'PT_IMPORT_VALRS_H_2013-14'!N21 -> 800.9603 | R20: =+'PT_IMPORT_VALRS_H_2014-15'!N21 -> 1623.1633 | S20: =+'PT_IMPORT_VALRS_H_2015-16'!N21 -> 1831.5235 | T20: =+'PT_Import_Val_2016-17 '!P20 -> 1638.1162 | U20: ='PT_Import_Val_2017-18'!P20 -> 1902.2741 | V20: ='PT_Import_Val_2018-19'!N21 -> 2149.4748 | W20: ='PT_Import_Val_2019-20'!N21 -> 3633.6413 | X20: ='PT_Import_Val_2020-21'!N21 -> 4325.214 | Y20: ='PT_Import_Val_2021-22'!N21 -> 7678.0227 | Z20: ='PT_Import_Val_2022-23'!N21 -> 9945.0763
A21: Others& | B21: 4 | C21: 4 | D21: 2397 | E21: 487 | F21: 17 | G21: 738 | H21: 1227 | I21: 3757 | J21: 4286 | K21: 4219 | L21: 5277 | M21: 4374.4749 | N21: 8163.9418 | O21: =+'PT_IMPORT_VALRS_H 2011-12'!N22 -> 7281.5423 | P21: =+'PT_IMPORT_VALRS_H 2012-13 '!N22 -> 8415.1961 | Q21: =+'PT_IMPORT_VALRS_H_2013-14'!N22 -> 11162.149 | R21: =+'PT_IMPORT_VALRS_H_2014-15'!N22 -> 11649.436 | S21: =+'PT_IMPORT_VALRS_H_2015-16'!N22 -> 10454.203 | T21: =+'PT_Import_Val_2016-17 '!P21 -> 13271.284 | U21: ='PT_Import_Val_2017-18'!P21 -> 19119.573 | V21: ='PT_Import_Val_2018-19'!N22 -> 26798.263 | W21: ='PT_Import_Val_2019-20'!N22 -> 19884.841 | X21: ='PT_Import_Val_2020-21'!N22+'PT_Import_Val_2020-21'!N23 -> 14104.198 | Y21: ='PT_Import_Val_2021-22'!N22+'PT_Import_Val_2021-22'!N23 -> 19522.736 | Z21: ='PT_Import_Val_2022-23'!N22+'PT_Import_Val_2022-23'!N23 -> 29582.301
A22: TOTAL PRODUCT IMPORT | B22: =SUM(B12:B21) -> 12274 | C22: =SUM(C12:C21) -> 14186 | D22: =SUM(D12:D21) -> 12093 | E22: =SUM(E12:E21) -> 7249 | F22: =SUM(F12:F21) -> 8847 | G22: =SUM(G12:G21) -> 9723 | H22: =SUM(H12:H21) -> 14887 | I22: =SUM(I12:I21) -> 27970 | ... Z22: =SUM(Z12:Z21) -> 215853.99
A24: TOTAL IMPORTS | B24: =+B10+B22 -> 27191 | C24: =+C10+C22 -> 54214 | D24: =+D10+D22 -> 78025 | E24: =+E10+E22 -> 67646 | F24: =+F10+F22 -> 85042 | G24: =+G10+G22 -> 93251 | H24: =+H10+H22 -> 131890 | I24: =+I10+I22 -> 199672 | ... Z24: =+Z10+Z22 -> 1476225.8
A26: PRODUCT EXPORT @
A27: LPG | B27: 0 | C27: 0 | D27: 0 | E27: 0 | F27: 0 | G27: 0 | H27: 306 | I27: 164 | J27: 342 | K27: 401 | L27: 456 | M27: 490.85 | N27: 693.3 | O27: =+'PT_IMPORT_VALRS_H 2011-12'!N26 -> 947.177 | P27: =+'PT_IMPORT_VALRS_H 2012-13 '!N26 -> 1294.03 | Q27: =+'PT_IMPORT_VALRS_H_2013-14'!N26 -> 1588.682 | R27: =+'PT_IMPORT_VALRS_H_2014-15'!N26 -> 1455.3213 | S27: =+'PT_IMPORT_VALRS_H_2015-16'!N26 -> 784.95 | T27: =+'PT_Import_Val_2016-17 '!P25 -> 1167.71 | U27: ='PT_Import_Val_2017-18'!P25 -> 1501.11 | V27: ='PT_Import_Val_2018-19'!N26 -> 1975.7371 | W27: ='PT_Import_Val_2019-20'!N26 -> 1970.4535 | X27: ='PT_Import_Val_2020-21'!N27 -> 1796.6654 | Y27: ='PT_Import_Val_2021-22'!N27 -> 3213.5824 | Z27: ='PT_Import_Val_2022-23'!N27 -> 3891.1622
A28: MS! | B28: 0 | C28: 139 | D28: 1442 | E28: 2570 | F28: 3011 | G28: 4021 | H28: 5625 | I28: 5843 | J28: 10191 | K28: 13614 | L28: 17810 | M28: 31203.411 | N28: 49480 | O28: =+'PT_IMPORT_VALRS_H 2011-12'!N27 -> 73981.818 | P28: =+'PT_IMPORT_VALRS_H 2012-13 '!N27 -> 95345.914 | Q28: =+'PT_IMPORT_VALRS_H_2013-14'!N27 -> 92977.32 | R28: =+'PT_IMPORT_VALRS_H_2014-15'!N27 -> 81971.029 | S28: =+'PT_IMPORT_VALRS_H_2015-16'!N27 -> 59575.392 | T28: =+'PT_Import_Val_2016-17 '!P26 -> 52919.542 | U28: ='PT_Import_Val_2017-18'!P26 -> 54580.02 | V28: ='PT_Import_Val_2018-19'!N27 -> 60418.809 | W28: ='PT_Import_Val_2019-20'!N27 -> 54511.864 | X28: ='PT_Import_Val_2020-21'!N28 -> 36529.618 | Y28: ='PT_Import_Val_2021-22'!N28 -> 81648.608 | Z28: ='PT_Import_Val_2022-23'!N28 -> 102799.61
A29: Naphtha | B29: 306 | C29: 520 | D29: 3273 | E29: 2300 | F29: 2325 | G29: 2653 | H29: 5030 | I29: 10787 | J29: 21431 | K29: 27365 | L29: 25055 | M29: 30317.999 | N29: 37138 | O29: =+'PT_IMPORT_VALRS_H 2011-12'!N28 -> 45619.746 | P29: =+'PT_IMPORT_VALRS_H 2012-13 '!N28 -> 43533.086 | Q29: =+'PT_IMPORT_VALRS_H_2013-14'!N28 -> 46059.171 | R29: =+'PT_IMPORT_VALRS_H_2014-15'!N28 -> 31618.999 | S29: =+'PT_IMPORT_VALRS_H_2015-16'!N28 -> 20056.51 | T29: =+'PT_Import_Val_2016-17 '!P27 -> 24615.901 | U29: ='PT_Import_Val_2017-18'!P27 -> 29074.807 | V29: ='PT_Import_Val_2018-19'!N28 -> 28893.121 | W29: ='PT_Import_Val_2019-20'!N28 -> 31508.549 | X29: ='PT_Import_Val_2020-21'!N29 -> 18642.821 | Y29: ='PT_Import_Val_2021-22'!N29 -> 37231.32 | Z29: ='PT_Import_Val_2022-23'!N29 -> 33356.575
A30: ATF# | B30: 0 | C30: 0 | D30: 174 | E30: 176 | F30: 790 | G30: 1950 | H30: 4448 | I30: 7077 | J30: 10254 | K30: 13555 | L30: 13498 | M30: 13331.226 | N30: 16140 | O30: =+'PT_IMPORT_VALRS_H 2011-12'!N29 -> 21856.645 | P30: =+'PT_IMPORT_VALRS_H 2012-13 '!N29 -> 25222.79 | Q30: =+'PT_IMPORT_VALRS_H_2013-14'!N29 -> 33246.309 | R30: =+'PT_IMPORT_VALRS_H_2014-15'!N29 -> 25412.905 | S30: =+'PT_IMPORT_VALRS_H_2015-16'!N29 -> 16007.081 | T30: =+'PT_Import_Val_2016-17 '!P28 -> 22294.138 | U30: ='PT_Import_Val_2017-18'!P28 -> 25347.954 | V30: ='PT_Import_Val_2018-19'!N29 -> 34029.995 | W30: ='PT_Import_Val_2019-20'!N29 -> 28458.271 | X30: ='PT_Import_Val_2020-21'!N30 -> 9376.8162 | Y30: ='PT_Import_Val_2021-22'!N30 -> 27111.727 | Z30: ='PT_Import_Val_2022-23'!N30 -> 58598.076
A31: SKO | B31: 0 | C31: 0 | D31: 0 | E31: 0 | F31: 0 | G31: 0 | H31: 460 | I31: 371 | J31: 541 | K31: 492 | L31: 362 | M31: 153.96 | N31: 141 | O31: =+'PT_IMPORT_VALRS_H 2011-12'!N30 -> 190.917 | P31: =+'PT_IMPORT_VALRS_H 2012-13 '!N30 -> 139.847 | Q31: =+'PT_IMPORT_VALRS_H_2013-14'!N30 -> 98.455 | R31: =+'PT_IMPORT_VALRS_H_2014-15'!N30 -> 81.344483 | S31: =+'PT_IMPORT_VALRS_H_2015-16'!N30 -> 35.31 | T31: =+'PT_Import_Val_2016-17 '!P29 -> 54.41 | U31: ='PT_Import_Val_2017-18'!P29 -> 68.12 | V31: ='PT_Import_Val_2018-19'!N30 -> 97.639977 | W31: ='PT_Import_Val_2019-20'!N30 -> 559.70069 | X31: ='PT_Import_Val_2020-21'!N31 -> 48.416583 | Y31: ='PT_Import_Val_2021-22'!N31 -> 76.918182 | Z31: ='PT_Import_Val_2022-23'!N31 -> 100.48099
A32: HSD | B32: 0 | C32: 0 | D32: 1872 | E32: 2548 | F32: 3547 | G32: 6763 | H32: 11782 | I32: 18654 | J32: 29198 | K32: 40871 | L32: 49670 | M32: 50929.825 | N32: 69300.3 | O32: =+'PT_IMPORT_VALRS_H 2011-12'!N31 -> 104571.92 | P32: =+'PT_IMPORT_VALRS_H 2012-13 '!N31 -> 115553.81 | Q32: =+'PT_IMPORT_VALRS_H_2013-14'!N31 -> 148138.13 | R32: =+'PT_IMPORT_VALRS_H_2014-15'!N31 -> 115149.03 | S32: =+'PT_IMPORT_VALRS_H_2015-16'!N31 -> 66492.321 | T32: =+'PT_Import_Val_2016-17 '!P30 -> 79857.261 | U32: ='PT_Import_Val_2017-18'!P30 -> 99454.07 | V32: ='PT_Import_Val_2018-19'!N31 -> 123518.62 | W32: ='PT_Import_Val_2019-20'!N31 -> 123919.27 | X32: ='PT_Import_Val_2020-21'!N32 -> 81610.751 | Y32: ='PT_Import_Val_2021-22'!N32 -> 164741.25 | Z32: ='PT_Import_Val_2022-23'!N32 -> 230813.46
A33: LDO | B33: 0 | C33: 0 | D33: 9 | E33: 23 | F33: 0 | G33: 0 | H33: 0 | I33: 0.5 | J33: 0.3 | K33: 0 | L33: 1.3 | M33: 87.1 | N33: 260 | O33: =+'PT_IMPORT_VALRS_H 2011-12'!N32 -> 331.1499 | P33: =+'PT_IMPORT_VALRS_H 2012-13 '!N32 -> 41.651 | Q33: =+'PT_IMPORT_VALRS_H_2013-14'!N32 -> 134.96718 | R33: =+'PT_IMPORT_VALRS_H_2014-15'!N32 -> 28.37 | S33: =+'PT_IMPORT_VALRS_H_2015-16'!N32 -> 0 | T33: =+'PT_Import_Val_2016-17 '!P31 -> 398.85739 | U33: ='PT_Import_Val_2017-18'!P31 -> 37.484147 | V33: ='PT_Import_Val_2018-19'!N32 -> 363.83345 | W33: ='PT_Import_Val_2019-20'!N32 -> 0 | X33: ='PT_Import_Val_2020-21'!N33 -> 0 | Y33: ='PT_Import_Val_2021-22'!N33 -> 0.221489 | Z33: ='PT_Import_Val_2022-23'!N33 -> 12.823656
A34: LOBS/ Lube Oil | B34: 0 | C34: 0 | D34: 0 | E34: 0 | F34: 24 | G34: 36 | H34: 23 | I34: 355 | J34: 1207 | K34: 691 | L34: 687 | M34: 120.6 | N34: 153.7 | O34: =+'PT_IMPORT_VALRS_H 2011-12'!N33 -> 180.7729 | P34: =+'PT_IMPORT_VALRS_H 2012-13 '!N33 -> 381.45422 | Q34: =+'PT_IMPORT_VALRS_H_2013-14'!N33 -> 138.35098 | R34: =+'PT_IMPORT_VALRS_H_2014-15'!N33 -> 99.553503 | S34: =+'PT_IMPORT_VALRS_H_2015-16'!N33 -> 127.08999 | T34: =+'PT_Import_Val_2016-17 '!P32 -> 103.74476 | U34: ='PT_Import_Val_2017-18'!P32 -> 118.35631 | V34: ='PT_Import_Val_2018-19'!N33 -> 106 | W34: ='PT_Import_Val_2019-20'!N33 -> 95.97 | X34: ='PT_Import_Val_2020-21'!N34 -> 92.944733 | Y34: ='PT_Import_Val_2021-22'!N34 -> 114.45312 | Z34: ='PT_Import_Val_2022-23'!N34 -> 204.87498
A35: Fuel Oil | B35: 0 | C35: 0 | D35: 320 | E35: 255 | F35: 902 | G35: 928 | H35: 1517 | I35: 2268 | J35: 4988 | K35: 6811 | L35: 12297 | M35: 10477.878 | N35: 15098 | O35: =+'PT_IMPORT_VALRS_H 2011-12'!N34 -> 25576.267 | P35: =+'PT_IMPORT_VALRS_H 2012-13 '!N34 -> 20415.477 | Q35: =+'PT_IMPORT_VALRS_H_2013-14'!N34 -> 22407.087 | R35: =+'PT_IMPORT_VALRS_H_2014-15'!N34 -> 14250.729 | S35: =+'PT_IMPORT_VALRS_H_2015-16'!N34 -> 4470.9867 | T35: =+'PT_Import_Val_2016-17 '!P33 -> 3929.7991 | U35: ='PT_Import_Val_2017-18'!P33 -> 5291.0196 | V35: ='PT_Import_Val_2018-19'!N34 -> 6537.1073 | W35: ='PT_Import_Val_2019-20'!N34 -> 3811.2168 | X35: ='PT_Import_Val_2020-21'!N35 -> 2318.3597 | Y35: ='PT_Import_Val_2021-22'!N35 -> 6633.0797 | Z35: ='PT_Import_Val_2022-23'!N35 -> 7834.1902
A36: Bitumen | B36: 0 | C36: 0 | D36: 0 | E36: 0 | F36: 0 | G36: 4 | H36: 31 | I36: 25 | J36: 77 | K36: 51 | L36: 64 | M36: 66.62 | N36: 124 | O36: =+'PT_IMPORT_VALRS_H 2011-12'!N35 -> 26.802217 | P36: =+'PT_IMPORT_VALRS_H 2012-13 '!N35 -> 281.21916 | Q36: =+'PT_IMPORT_VALRS_H_2013-14'!N35 -> 321.31154 | R36: =+'PT_IMPORT_VALRS_H_2014-15'!N35 -> 245.2212 | S36: =+'PT_IMPORT_VALRS_H_2015-16'!N35 -> 176.19691 | T36: =+'PT_Import_Val_2016-17 '!P34 -> 36.968027 | U36: ='PT_Import_Val_2017-18'!P34 -> 118.60878 | V36: ='PT_Import_Val_2018-19'!N35 -> 71.797439 | W36: ='PT_Import_Val_2019-20'!N35 -> 88.600216 | X36: ='PT_Import_Val_2020-21'!N36 -> 23.485345 | Y36: ='PT_Import_Val_2021-22'!N36 -> 27.863057 | Z36: ='PT_Import_Val_2022-23'!N36 -> 42.412268
A37: Others% | B37: 0 | C37: 39 | D37: 582 | E37: 413 | F37: 269 | G37: 426 | H37: 706 | I37: 4429 | J37: 2865 | K37: 6938 | L37: 2575 | M37: 7507.9443 | N37: 8332.4 | O37: =+'PT_IMPORT_VALRS_H 2011-12'!N36 -> 11361.012 | P37: =+'PT_IMPORT_VALRS_H 2012-13 '!N36 -> 17880.317 | Q37: =+'PT_IMPORT_VALRS_H_2013-14'!N36 -> 23169.28 | R37: =+'PT_IMPORT_VALRS_H_2014-15'!N36 -> 18267.293 | S37: =+'PT_IMPORT_VALRS_H_2015-16'!N36 -> 9053.7429 | T37: =+'PT_Import_Val_2016-17 '!P35 -> 9514.3118 | U37: ='PT_Import_Val_2017-18'!P35 -> 9796.21 | V37: ='PT_Import_Val_2018-19'!N36 -> 11683.859 | W37: ='PT_Import_Val_2019-20'!N36 -> 9093.6475 | X37: ='PT_Import_Val_2020-21'!N38+'PT_Import_Val_2020-21'!N37 -> 6727.8321 | Y37: ='PT_Import_Val_2021-22'!N38+'PT_Import_Val_2021-22'!N37 -> 11001.981 | Z37: ='PT_Import_Val_2022-23'!N38+'PT_Import_Val_2022-23'!N37 -> 21075.002
A38: TOTAL EXPORT | B38: =SUM(B27:B37) -> 306 | C38: =SUM(C27:C37) -> 698 | D38: =SUM(D27:D37) -> 7672 | E38: =SUM(E27:E37) -> 8285 | F38: =SUM(F27:F37) -> 10868 | G38: =SUM(G27:G37) -> 16781 | H38: =SUM(H27:H37) -> 29928 | I38: =SUM(I27:I37) -> 49973.5 | ... Z38: =SUM(Z27:Z37) -> 458728.67
A40: NET IMPORT | B40: =+B24-B38 -> 26885 | C40: =+C24-C38 -> 53516 | D40: =+D24-D38 -> 70353 | E40: =+E24-E38 -> 59361 | F40: =+F24-F38 -> 74174 | G40: =+G24-G38 -> 76470 | H40: =+H24-H38 -> 101962 | I40: =+I24-I38 -> 149698.5 | ... Z40: =+Z24-Z38 -> 1017497.1
A42: Net Product Export | B42: =+B38-B22 -> -11968 | C42: =+C38-C22 -> -13488 | D42: =+D38-D22 -> -4421 | E42: =+E38-E22 -> 1036 | F42: =+F38-F22 -> 2021 | G42: =+G38-G22 -> 7058 | H42: =+H38-H22 -> 15041 | I42: =+I38-I22 -> 22003.5 | ... Z42: =+Z38-Z22 -> 242874.68
A43: Source: Oil Companies & DGCIS P= Provisional
A44: Notes:
A45: RIL SEZ imports/exports included in country's import/export data
A46: ^LNG import not included
A47: & Others in import include Petcoke, Paraffin wax, Petroleum Jelly, Aviation Gas, MTBE, Reformate etc.
...

Sheet PT_Import_Val_2022-23
E4: Petroleum Planning & Analysis Cell
A6: 2022-23
A7: (` Crore)
A8: Import/Export of Crude oil and Petroleum Products
A9: IMPORT/EXPORT | B9: APRIL | C9: MAY | D9: JUNE | E9: JULY | F9: AUGUST | G9: SEPTEMBER | H9: OCTOBER | I9: NOVEMBER | J9: DECEMBER | K9: JANUARY | L9: FEBRUARY | M9: MARCH | N9: TOTAL
A10: IMPORT^
A11: CRUDE OIL | B11: 128800.07 | C11: 119633.62 | D11: 121897.64 | E11: 128755.46 | F11: 104567.32 | G11: 95157.742 | H11: 99194.386 | I11: 100258.76 | J11: 94253.237 | K11: 92441.855 | L11: 85798.259 | M11: 89613.479 | N11: =SUM(B11:M11) -> 1260371.8
A12: PRODUCTS
A13: LPG | B13: 11742.672 | C13: 9255.451 | D13: 7620.4483 | E13: 8397.3697 | F13: 8569.8646 | G13: 7569.7403 | H13: 6864.8739 | I13: 9211.2182 | J13: 9489.0789 | K13: 8825.4003 | L13: 10878.431 | M13: 8766.6198 | N13: =SUM(B13:M13) -> 107191.17
A14: MS | B14: 0 | C14: 314.4506 | D14: 1620.7635 | E14: 619.8408 | F14: 0.1369074 | G14: 1395.2889 | H14: 2433.863 | I14: 1620.1604 | J14: 841.67997 | K14: 0.2713627 | L14: 0 | M14: 0 | N14: =SUM(B14:M14) -> 8846.4554
A15: Naphtha | B15: 241.16156 | C15: 260.22227 | D15: 13.868198 | E15: 924.00607 | F15: 475.24784 | G15: 355.42526 | H15: 636.94037 | I15: 173.61044 | J15: 388.0545 | K15: 184.14578 | L15: 687.09829 | M15: 441.55078 | N15: =SUM(B15:M15) -> 4781.3313
A16: ATF | B16: 0 | C16: 0.0013425 | D16: 0 | E16: 0 | F16: 0 | G16: 0 | H16: 0 | I16: 0 | J16: 0 | K16: 0 | L16: 0 | M16: 0 | N16: =SUM(B16:M16) -> 0.0013425
A17: SKO | B17: 0 | C17: 0 | D17: 0 | E17: 0 | F17: 0 | G17: 0 | H17: 0 | I17: 0 | J17: 0 | K17: 0 | L17: 0 | M17: 0 | N17: =SUM(B17:M17) -> 0
A18: HSD | B18: 22.398763 | C18: 102.77772 | D18: 1530.4304 | E18: 1432.4402 | F18: 86.03771 | G18: 14.528648 | H18: 91.96575 | I18: 66.538544 | J18: 118.05043 | K18: 45.498867 | L18: 43.608899 | M18: 29.76553 | N18: =SUM(B18:M18) -> 3584.0415
A19: LOBS/ Lube oil | B19: 1591.0748 | C19: 1680.7704 | D19: 1579.928 | E19: 2086.7115 | F19: 1616.9316 | G19: 1282.3926 | H19: 1887.5094 | I19: 1420.5143 | J19: 1204.4994 | K19: 1183.353 | L19: 1514.6667 | M19: 1401.0159 | N19: =SUM(B19:M19) -> 18449.368
A20: Fuel Oil | B20: 5016.0753 | C20: 2519.2737 | D20: 3067.6493 | E20: 3545.6688 | F20: 2952.6101 | G20: 2178.9693 | H20: 2472.8859 | I20: 2037.8983 | J20: 2952.3116 | K20: 2764.7977 | L20: 1893.7301 | M20: 2072.376 | N20: =SUM(B20:M20) -> 33474.246
A21: Bitumen | B21: 1047.5565 | C21: 1020.9421 | D21: 804.34878 | E21: 451.78709 | F21: 236.91318 | G21: 394.69968 | H21: 773.57192 | I21: 1105.4384 | J21: 1021.8655 | K21: 914.54585 | L21: 986.62272 | M21: 1186.7844 | N21: =SUM(B21:M21) -> 9945.0763
A22: Petcoke | B22: 1704.7949 | C22: 1675.7071 | D22: 1461.5899 | E22: 1787.0969 | F22: 1351.0164 | G22: 1020.8874 | H22: 1587.7222 | I22: 1709.942 | J22: 971.62532 | K22: 1356.0312 | L22: 1351.3822 | M22: 2179.5633 | N22: =SUM(B22:M22) -> 18157.359
A23: Others& | B23: 1091.9775 | C23: 1318.3056 | D23: 765.33193 | E23: 618.96919 | F23: 1120.1187 | G23: 646.20744 | H23: 604.47946 | I23: 673.19644 | J23: 855.07457 | K23: 1177.0665 | L23: 589.70741 | M23: 1964.5072 | N23: =SUM(B23:M23) -> 11424.942
A24: PRODUCT IMPORT* | B24: =SUM(B13:B23) -> 22457.712 | C24: =SUM(C13:C23) -> 18147.902 | D24: =SUM(D13:D23) -> 18464.358 | E24: =SUM(E13:E23) -> 19863.89 | F24: =SUM(F13:F23) -> 16408.877 | G24: =SUM(G13:G23) -> 14858.14 | H24: =SUM(H13:H23) -> 17353.812 | I24: =SUM(I13:I23) -> 18018.517 | ... N24: =SUM(N13:N23) -> 215853.99
A25: TOTAL IMPORT | B25: =+B24+B11 -> 151257.78 | C25: =+C24+C11 -> 137781.52 | D25: =+D24+D11 -> 140362 | E25: =+E24+E11 -> 148619.36 | F25: =+F24+F11 -> 120976.19 | G25: =+G11+G24 -> 110015.88 | H25: =+H11+H24 -> 116548.2 | I25: =+I11+I24 -> 118277.28 | J25: =+J11+J24 -> 112095.48 | K25: =+K11+K24 -> 108892.97 | L25: =+L11+L24 -> 103743.51 | M25: =+M11+M24 -> 107655.66 | N25: =+N11+N24 -> 1476225.8
A26: PRODUCT EXPORT @
A27: LPG | B27: 396.9239 | C27: 418.97014 | D27: 413.13719 | E27: 312.20178 | F27: 287.6589 | G27: 270.15053 | H27: 278.24232 | I27: 254.63032 | J27: 276.83418 | K27: 315.53337 | L27: 267.80112 | M27: 399.07843 | N27: =SUM(B27:M27) -> 3891.1622
A28: MS! | B28: 12030.341 | C28: 11527.746 | D28: 12351.79 | E28: 9095.5542 | F28: 7325.3684 | G28: 4580.6618 | H28: 3312.6717 | I28: 5736.1601 | J28: 8138.8676 | K28: 8424.6507 | L28: 9774.3539 | M28: 10501.447 | N28: =SUM(B28:M28) -> 102799.61
A29: Naphtha$ | B29: 4217.7986 | C29: 3643.5417 | D29: 5154.5869 | E29: 2168.2852 | F29: 2274.9054 | G29: 2331.0189 | H29: 2009.0469 | I29: 2335.9554 | J29: 2245.7181 | K29: 1812.003 | L29: 2342.9942 | M29: 2820.7207 | N29: =SUM(B29:M29) -> 33356.575
A30: ATF# | B30: 2889.1223 | C30: 4073.1044 | D30: 6051.4933 | E30: 5085.6447 | F30: 6365.5962 | G30: 5317.8387 | H30: 5347.4238 | I30: 4880.0982 | J30: 4543.6761 | K30: 4429.2606 | L30: 4604.4054 | M30: 5010.4128 | N30: =SUM(B30:M30) -> 58598.076
A31: SKO | B31: 17.401125 | C31: 6.3677977 | D31: 12.293059 | E31: 10.858749 | F31: 4.588173 | G31: 7.4526338 | H31: 6.4208078 | I31: 8.031776 | J31: 8.2406516 | K31: 7.3006848 | L31: 4.5058237 | M31: 7.0197049 | N31: =SUM(B31:M31) -> 100.48099
A32: HSD | B32: 22851.559 | C32: 27541.927 | D32: 24876.92 | E32: 19133.376 | F32: 19619.725 | G32: 21040.054 | H32: 17901.671 | I32: 15873.609 | J32: 17381.545 | K32: 14375.319 | L32: 14676.246 | M32: 15541.504 | N32: =SUM(B32:M32) -> 230813.46
A33: LDO | B33: 0.78996 | C33: 1.03938 | D33: 0.86812 | E33: 1.183684 | F33: 0.742832 | G33: 1.004124 | H33: 1.264924 | I33: 1.200176 | J33: 1.515756 | K33: 0.8352 | L33: 1.14728 | M33: 1.23222 | N33: =SUM(B33:M33) -> 12.823656
A34: LOBS/ Lube Oil | B34: 34.47029 | C34: 6.349315 | D34: 16.673983 | E34: 13.010111 | F34: 8.0334882 | G34: 13.616913 | H34: 7.8942673 | I34: 11.478333 | J34: 10.097788 | K34: 10.365422 | L34: 6.7416974 | M34: 66.143376 | N34: =SUM(B34:M34) -> 204.87498
A35: Fuel Oil | B35: 261.25677 | C35: 460.71081 | D35: 612.44256 | E35: 722.88598 | F35: 1046.9749 | G35: 546.31845 | H35: 968.49737 | I35: 720.73025 | J35: 925.50903 | K35: 685.22129 | L35: 324.53806 | M35: 559.10474 | N35: =SUM(B35:M35) -> 7834.1902
A36: Bitumen | B36: 0.1164737 | C36: 0.7778321 | D36: 5.6692852 | E36: 0.2459777 | F36: 0.0999142 | G36: 10.242349 | H36: 10.962852 | I36: 0.4832893 | J36: 0.4495835 | K36: 0.2045987 | L36: 1.3071378 | M36: 11.852975 | N36: =SUM(B36:M36) -> 42.412268
A37: Petcoke / CBFS | B37: 15.541078 | C37: 124.093 | D37: 129.88167 | E37: 35.265887 | F37: 32.755974 | G37: 13.802129 | H37: 0 | I37: 0 | J37: 0 | K37: 0 | L37: 24.489539 | M37: 272.24174 | N37: =SUM(B37:M37) -> 648.07102
A38: Others% | B38: 1788.2917 | C38: 2177.1993 | D38: 1907.0854 | E38: 1515.6644 | F38: 1722.7041 | G38: 1225.168 | H38: 852.01871 | I38: 1278.5136 | J38: 3372.831 | K38: 1201.6123 | L38: 1738.2354 | M38: 1647.6068 | N38: =SUM(B38:M38) -> 20426.931
A39: TOTAL PRODUCT EXPORT | B39: =SUM(B27:B38) -> 44503.613 | C39: =SUM(C27:C38) -> 49981.827 | D39: =SUM(D27:D38) -> 51532.842 | E39: =SUM(E27:E38) -> 38094.177 | F39: =SUM(F27:F38) -> 38689.153 | G39: =SUM(G27:G38) -> 35357.329 | H39: =SUM(H27:H38) -> 30696.114 | I39: =SUM(I27:I38) -> 31100.891 | ... N39: =SUM(N27:N38) -> 458728.67
A40: NET IMPORT | B40: =+B25-B39 -> 106754.16 | C40: =+C25-C39 -> 87799.697 | D40: =+D25-D39 -> 88829.156 | E40: =+E25-E39 -> 110525.18 | F40: =+F25-F39 -> 82287.04 | G40: =+G25-G39 -> 74658.552 | H40: =+H25-H39 -> 85852.083 | I40: =+I25-I39 -> 87176.385 | ... N40: =+N25-N39 -> 1017497.1
A41: Source: Oil Companies & DGCIS
A42: Notes:
A43: RIL SEZ imports/exports included in country's import/export data
A44: ^LNG import not included
...

Sheet PT_Import_Val_2021-22
E4: Petroleum Planning & Analysis Cell
A6: 2021-22
A7: (` Crore)
A8: Import/Export of Crude oil and Petroleum Products
A9: IMPORT/EXPORT | B9: APRIL | C9: MAY | D9: JUNE | E9: JULY | F9: AUGUST | G9: SEPTEMBER | H9: OCTOBER | I9: NOVEMBER | J9: DECEMBER | K9: JANUARY | L9: FEBRUARY | M9: MARCH | N9: TOTAL
A10: IMPORT^
A11: CRUDE OIL | B11: 63309.499 | C11: 60800.383 | D11: 61073.299 | E11: 59460.95 | F11: 67310.66 | G11: 69109.876 | H11: 72054.197 | I11: 79009.389 | J11: 81771.142 | K11: 86692.515 | L11: 87441.416 | M11: 113228.87 | N11: =SUM(B11:M11) -> 901262.19
A12: PRODUCTS
A13: LPG | B13: 4331.0805 | C13: 3901.8497 | D13: 5595.7045 | E13: 6495.7335 | F13: 8248.4288 | G13: 7704.7651 | H13: 9772.1868 | I13: 10281.785 | J13: 9846.5424 | K13: 7748.1724 | L13: 7419.0824 | M13: 10123.066 | N13: =SUM(B13:M13) -> 91468.398
A14: MS | B14: 349.45504 | C14: 0 | D14: 0 | E14: 0.1478954 | F14: 0 | G14: 592.97964 | H14: 2753.5998 | I14: 198.40835 | J14: 0.1373363 | K14: 0 | L14: 0.0749366 | M14: 0 | N14: =SUM(B14:M14) -> 3894.803
A15: Naphtha | B15: 169.37454 | C15: 179.87095 | D15: 184.24156 | E15: 0 | F15: 0 | G15: 0 | H15: 0 | I15: 121.39174 | J15: 0 | K15: 0 | L15: 0 | M15: 843.91669 | N15: =SUM(B15:M15) -> 1498.7955
A16: ATF | B16: 0 | C16: 0 | D16: 0 | E16: 0 | F16: 0 | G16: 0 | H16: 0 | I16: 0 | J16: 0 | K16: 0 | L16: 0 | M16: 0 | N16: =SUM(B16:M16) -> 0
A17: SKO | B17: 0 | C17: 0 | D17: 0 | E17: 0 | F17: 0 | G17: 0 | H17: 0 | I17: 0 | J17: 0 | K17: 0 | L17: 0 | M17: 0 | N17: =SUM(B17:M17) -> 0
A18: HSD | B18: 10.85699 | C18: 19.54261 | D18: 6.5960564 | E18: 4.8623181 | F18: 20.751588 | G18: 21.584828 | H18: 10.921709 | I18: 35.792882 | J18: 30.897299 | K18: 17.471873 | L18: 35.573635 | M18: 38.134252 | N18: =SUM(B18:M18) -> 252.98604
A19: LOBS/ Lube oil | B19: 1866.1582 | C19: 1665.0694 | D19: 1332.6024 | E19: 1368.8435 | F19: 1584.2582 | G19: 1559.2016 | H19: 2181.2364 | I19: 1442.3871 | J19: 2130.4848 | K19: 1053.875 | L19: 1459.0109 | M19: 2061.1263 | N19: =SUM(B19:M19) -> 19704.254
A20: Fuel Oil | B20: 2288.4191 | C20: 1770.4729 | D20: 1770.7152 | E20: 3191.2333 | F20: 2269.873 | G20: 1392.6538 | H20: 2786.0344 | I20: 2071.8881 | J20: 3041.7942 | K20: 2976.1114 | L20: 3784.2554 | M20: 5471.331 | N20: =SUM(B20:M20) -> 32814.782
A21: Bitumen | B21: 844.6063 | C21: 680.32935 | D21: 537.62194 | E21: 406.94049 | F21: 303.79641 | G21: 405.42638 | H21: 524.57537 | I21: 635.58946 | J21: 838.6689 | K21: 738.91371 | L21: 744.02557 | M21: 1017.5288 | N21: =SUM(B21:M21) -> 7678.0227
A22: Petcoke | B22: 62.365736 | C22: 347.4716 | D22: 352.19206 | E22: 618.59162 | F22: 299.97308 | G22: 360.67321 | H22: 595.86901 | I22: 717.38931 | J22: 1775.9366 | K22: 1478.8462 | L22: 866.01488 | M22: 727.93527 | N22: =SUM(B22:M22) -> 8203.2586
A23: Others& | B23: 975.83006 | C23: 681.40746 | D23: 826.37619 | E23: 1313.1364 | F23: 945.27455 | G23: 1888.0131 | H23: 792.89358 | I23: 591.4308 | J23: 944.92477 | K23: 1122.3829 | L23: 568.23391 | M23: 669.57356 | N23: =SUM(B23:M23) -> 11319.477
A24: PRODUCT IMPORT* | B24: =SUM(B13:B23) -> 10898.147 | C24: =SUM(C13:C23) -> 9246.0139 | D24: =SUM(D13:D23) -> 10606.05 | E24: =SUM(E13:E23) -> 13399.489 | F24: =SUM(F13:F23) -> 13672.356 | G24: =SUM(G13:G23) -> 13925.298 | H24: =SUM(H13:H23) -> 19417.317 | I24: =SUM(I13:I23) -> 16096.063 | ... N24: =SUM(N13:N23) -> 176834.78
A25: TOTAL IMPORT | B25: =+B24+B11 -> 74207.645 | C25: =+C24+C11 -> 70046.397 | D25: =+D24+D11 -> 71679.349 | E25: =+E24+E11 -> 72860.439 | F25: =+F24+F11 -> 80983.016 | G25: =+G11+G24 -> 83035.174 | H25: =+H11+H24 -> 91471.514 | I25: =+I11+I24 -> 95105.452 | J25: =+J11+J24 -> 100380.53 | K25: =+K11+K24 -> 101828.29 | L25: =+L11+L24 -> 102317.69 | M25: =+M11+M24 -> 134181.48 | N25: =+N11+N24 -> 1078097
A26: PRODUCT EXPORT @
A27: LPG | B27: 232.13622 | C27: 247.87268 | D27: 174.20451 | E27: 164.31052 | F27: 242.75606 | G27: 263.9085 | H27: 265.21135 | I27: 326.87479 | J27: 377.79335 | K27: 349.24289 | L27: 302.89778 | M27: 266.37378 | N27: =SUM(B27:M27) -> 3213.5824
A28: MS! | B28: 4405.4637 | C28: 6512.2124 | D28: 5894.7915 | E28: 5486.9031 | F28: 4714.781 | G28: 4648.2508 | H28: 6265.8856 | I28: 6181.933 | J28: 7997.3764 | K28: 7040.8193 | L28: 8675.3499 | M28: 13824.841 | N28: =SUM(B28:M28) -> 81648.608
A29: Naphtha$ | B29: 1936.357 | C29: 2184.3757 | D29: 2867.2176 | E29: 2410.0106 | F29: 3074.6301 | G29: 3259.2608 | H29: 3027.8431 | I29: 3413.5411 | J29: 3457.3274 | K29: 2885.888 | L29: 2792.9087 | M29: 5921.9597 | N29: =SUM(B29:M29) -> 37231.32
A30: ATF# | B30: 1054.0463 | C30: 1700.8093 | D30: 2085.926 | E30: 1521.1799 | F30: 1389.7583 | G30: 1281.2574 | H30: 2439.0397 | I30: 2905.1335 | J30: 2768.2246 | K30: 2525.348 | L30: 2627.922 | M30: 4813.0825 | N30: =SUM(B30:M30) -> 27111.727
A31: SKO | B31: 6.0118874 | C31: 5.899197 | D31: 8.8274251 | E31: 5.6966829 | F31: 3.2972661 | G31: 5.337546 | H31: 5.4742504 | I31: 8.0263914 | J31: 7.4064675 | K31: 6.8083256 | L31: 6.6603482 | M31: 7.4723943 | N31: =SUM(B31:M31) -> 76.918182
A32: HSD | B32: 7212.9991 | C32: 11833.966 | D32: 12122.688 | E32: 10066.061 | F32: 11127.397 | G32: 12496.825 | H32: 15298.122 | I32: 14150.787 | J32: 14804.945 | K32: 14187.667 | L32: 14940.456 | M32: 26499.334 | N32: =SUM(B32:M32) -> 164741.25
A33: LDO | B33: 0 | C33: 0 | D33: 0 | E33: 0 | F33: 0 | G33: 0 | H33: 0 | I33: 0 | J33: 0.111848 | K33: 0.109641 | L33: 0 | M33: 0 | N33: =SUM(B33:M33) -> 0.221489
A34: LOBS/ Lube Oil | B34: 3.33 | C34: 0.79 | D34: 6.01 | E34: 3.11 | F34: 7.83 | G34: 5.5 | H34: 4.85 | I34: 5.69 | J34: 16.72 | K34: 6.04 | L34: 34.94 | M34: 19.64312 | N34: =SUM(B34:M34) -> 114.45312
A35: Fuel Oil | B35: 287.78609 | C35: 774.17463 | D35: 654.58601 | E35: 1063.5744 | F35: 574.9572 | G35: 503.14039 | H35: 450.89346 | I35: 265.32013 | J35: 480.72942 | K35: 617.62004 | L35: 400.74348 | M35: 559.5545 | N35: =SUM(B35:M35) -> 6633.0797
A36: Bitumen | B36: 0.7120126 | C36: 0 | D36: 0 | E36: 0 | F36: 0 | G36: 8.6388581 | H36: 18.512186 | I36: 0 | J36: 0 | K36: 0 | L36: 0 | M36: 0 | N36: =SUM(B36:M36) -> 27.863057
A37: Petcoke / CBFS | B37: 2.5674964 | C37: 0.40168055 | D37: 0.79579588 | E37: 0.63448767 | F37: 148.59804 | G37: 158.32309 | H37: 190.77251 | I37: 0 | J37: 0.41038355 | K37: 0 | L37: 33.3 | M37: 17.512615 | N37: =SUM(B37:M37) -> 553.3161
A38: Others% | B38: 1006.286 | C38: 1112.8165 | D38: 971.15315 | E38: 1088.2538 | F38: 405.77332 | G38: 567.8816 | H38: 832.52431 | I38: 588.70743 | J38: 743.1362 | K38: 1062.0379 | L38: 851.29085 | M38: 1218.8039 | N38: =SUM(B38:M38) -> 10448.665
A39: TOTAL PRODUCT EXPORT | B39: =SUM(B27:B38) -> 16147.696 | C39: =SUM(C27:C38) -> 24373.318 | D39: =SUM(D27:D38) -> 24786.2 | E39: =SUM(E27:E38) -> 21809.734 | F39: =SUM(F27:F38) -> 21689.779 | G39: =SUM(G27:G38) -> 23198.324 | H39: =SUM(H27:H38) -> 28799.128 | I39: =SUM(I27:I38) -> 27846.013 | ... N39: =SUM(N27:N38) -> 331801
A40: NET IMPORT | B40: =+B25-B39 -> 58059.949 | C40: =+C25-C39 -> 45673.079 | D40: =+D25-D39 -> 46893.148 | E40: =+E25-E39 -> 51050.705 | F40: =+F25-F39 -> 59293.237 | G40: =+G25-G39 -> 59836.85 | H40: =+H25-H39 -> 62672.386 | I40: =+I25-I39 -> 67259.439 | ... N40: =+N25-N39 -> 746295.97
A41: Source: Oil Companies & DGCIS
A42: Notes:
A43: RIL SEZ imports/exports included in country's import/export data
A44: ^LNG import not included
...

Sheet PT_Import_Val_2020-21
E4: Petroleum Planning & Analysis Cell
A6: 2020-21
A7: (` Crore)
A8: Import/Export of Crude oil and Petroleum Products
A9: IMPORT/EXPORT | B9: APRIL | C9: MAY | D9: JUNE | E9: JULY | F9: AUGUST | G9: SEPTEMBER | H9: OCTOBER | I9: NOVEMBER | J9: DECEMBER | K9: JANUARY | L9: FEBRUARY | M9: MARCH | N9: TOTAL
A10: IMPORT^
A11: CRUDE OIL | B11: 23097.821 | C11: 17134.222 | D11: 24391.229 | E11: 28431.994 | F11: 40659.068 | G11: 34353.851 | H11: 33074.492 | I11: 40926.854 | J11: 52165.863 | K11: 55990.925 | L11: 48033.559 | M11: 61518.692 | N11: =SUM(B11:M11) -> 459778.57
A12: PRODUCTS
A13: LPG | B13: 3028.6634 | C13: 4080.3823 | D13: 3267.7466 | E13: 2565.3385 | F13: 3400.6783 | G13: 4559.2961 | H13: 4185.4035 | I13: 4774.5681 | J13: 5254.257 | K13: 5572.3051 | L13: 6807.5726 | M13: 6256.247 | N13: =SUM(B13:M13) -> 53752.459
A14: MS | B14: 0.4033338 | C14: 0 | D14: 101.93461 | E14: 115.63666 | F14: 109.0484 | G14: 230.52867 | H14: 399.56266 | I14: 473.67175 | J14: 2016.776 | K14: 513.69703 | L14: 357.41354 | M14: 630.95254 | N14: =SUM(B14:M14) -> 4949.6252
A15: Naphtha | B15: 63.385744 | C15: 86.609989 | D15: 464.45647 | E15: 488.29295 | F15: 422.69161 | G15: 287.53548 | H15: 472.80766 | I15: 540.05155 | J15: 272.7171 | K15: 170.25713 | L15: 425.83151 | M15: 149.40643 | N15: =SUM(B15:M15) -> 3844.0436
A16: ATF | B16: 0.0025391 | C16: 0.0010004 | D16: 0 | E16: 0.0027309 | F16: 0 | G16: 0 | H16: 0.0003558 | I16: 0 | J16: 0 | K16: 0 | L16: 0.0020701 | M16: 0 | N16: =SUM(B16:M16) -> 0.0086963
A17: SKO | B17: 0 | C17: 0 | D17: 0.0026053 | E17: 9.375249 | F17: 0 | G17: 0.6224536 | H17: 2.0913015 | I17: 0.0183525 | J17: 0.0256935 | K17: 0 | L17: 0 | M17: 0.0018431 | N17: =SUM(B17:M17) -> 12.137498
A18: HSD | B18: 83.844894 | C18: 74.723229 | D18: 199.16737 | E18: 394.97171 | F18: 11.737663 | G18: 7.5919417 | H18: 35.406694 | I18: 9.2796564 | J18: 797.02639 | K18: 242.43264 | L18: 67.237494 | M18: 36.623313 | N18: =SUM(B18:M18) -> 1960.043
A19: LOBS/ Lube oil | B19: 735.31662 | C19: 407.72032 | D19: 443.65466 | E19: 747.21748 | F19: 886.39726 | G19: 922.9987 | H19: 1127.8781 | I19: 1370.4987 | J19: 1344.1348 | K19: 1452.6091 | L19: 1385.0957 | M19: 1346.7316 | N19: =SUM(B19:M19) -> 12170.253
A20: Fuel Oil | B20: 555.10848 | C20: 639.86339 | D20: 964.77656 | E20: 2459.7076 | F20: 1005.4711 | G20: 493.74213 | H20: 328.04894 | I20: 495.9697 | J20: 1138.1601 | K20: 949.73542 | L20: 2109.5524 | M20: 3171.5483 | N20: =SUM(B20:M20) -> 14311.684
A21: Bitumen | B21: 191.87442 | C21: 180.86788 | D21: 274.95764 | E21: 290.28508 | F21: 154.83377 | G21: 195.8835 | H21: 196.86052 | I21: 293.70642 | J21: 464.99007 | K21: 670.91221 | L21: 697.81682 | M21: 712.22571 | N21: =SUM(B21:M21) -> 4325.214
A22: Petcoke | B22: 386.73428 | C22: 1138.4077 | D22: 501.1175 | E22: 630.69387 | F22: 592.57781 | G22: 482.70316 | H22: 519.76978 | I22: 495.57565 | J22: 500.87193 | K22: 307.3214 | L22: 150.25827 | M22: 703.6213 | N22: =SUM(B22:M22) -> 6409.6527
A23: Others& | B23: 628.77301 | C23: 478.89014 | D23: 762.24359 | E23: 872.5749 | F23: 476.28247 | G23: 369.22605 | H23: 523.00392 | I23: 388.15877 | J23: 494.1323 | K23: 825.28411 | L23: 931.25181 | M23: 944.72381 | N23: =SUM(B23:M23) -> 7694.5449
A24: PRODUCT IMPORT* | B24: =SUM(B13:B23) -> 5674.1067 | C24: =SUM(C13:C23) -> 7087.466 | D24: =SUM(D13:D23) -> 6980.0576 | E24: =SUM(E13:E23) -> 8574.0968 | F24: =SUM(F13:F23) -> 7059.7184 | G24: =SUM(G13:G23) -> 7550.1282 | H24: =SUM(H13:H23) -> 7790.8334 | I24: =SUM(I13:I23) -> 8841.4987 | ... N24: =SUM(N13:N23) -> 109429.67
A25: TOTAL IMPORT | B25: =+B24+B11 -> 28771.928 | C25: =+C24+C11 -> 24221.688 | D25: =+D24+D11 -> 31371.286 | E25: =+E24+E11 -> 37006.09 | F25: =+F24+F11 -> 47718.787 | G25: =+G11+G24 -> 41903.979 | H25: =+H11+H24 -> 40865.325 | I25: =+I11+I24 -> 49768.353 | J25: =+J11+J24 -> 64448.955 | K25: =+K11+K24 -> 66695.479 | L25: =+L11+L24 -> 60965.591 | M25: =+M11+M24 -> 75470.774 | N25: =+N11+N24 -> 569208.23
A26: PRODUCT EXPORT @
A27: LPG | B27: 155.44688 | C27: 91.700391 | D27: 105.91984 | E27: 103.8657 | F27: 114.54351 | G27: 128.22866 | H27: 124.21466 | I27: 143.86175 | J27: 170.76146 | K27: 195.88343 | L27: 207.21724 | M27: 255.02191 | N27: =SUM(B27:M27) -> 1796.6654
A28: MS! | B28: 1381.7336 | C28: 2194.3455 | D28: 2815.1928 | E28: 3024.7832 | F28: 2809.2707 | G28: 2847.7059 | H28: 2299.5541 | I28: 2777.0954 | J28: 3131.5067 | K28: 3422.3366 | L28: 3935.5538 | M28: 5890.5396 | N28: =SUM(B28:M28) -> 36529.618
A29: Naphtha$ | B29: 655.6674 | C29: 781.74544 | D29: 1164.3824 | E29: 895.23251 | F29: 1622.3321 | G29: 1717.4901 | H29: 801.60635 | I29: 1212.3563 | J29: 1846.2793 | K29: 2210.2161 | L29: 2282.7483 | M29: 3452.765 | N29: =SUM(B29:M29) -> 18642.821
A30: ATF# | B30: 628.99369 | C30: 436.58389 | D30: 574.16679 | E30: 579.59254 | F30: 372.74702 | G30: 633.83367 | H30: 423.12917 | I30: 718.48285 | J30: 917.25792 | K30: 989.10263 | L30: 1581.7586 | M30: 1521.1675 | N30: =SUM(B30:M30) -> 9376.8162
A31: SKO | B31: 0.0951482 | C31: 0.0775353 | D31: 1.5432244 | E31: 4.4183477 | F31: 2.1868383 | G31: 1.9761498 | H31: 6.2903462 | I31: 5.5339283 | J31: 6.6919014 | K31: 6.7677022 | L31: 5.432813 | M31: 7.4026479 | N31: =SUM(B31:M31) -> 48.416583
A32: HSD | B32: 5441.8586 | C32: 4816.3194 | D32: 5162.7118 | E32: 5836.6398 | F32: 7935.0186 | G32: 6628.5666 | H32: 5699.8199 | I32: 5811.1369 | J32: 7591.7586 | K32: 7555.9882 | L32: 7727.0684 | M32: 11403.865 | N32: =SUM(B32:M32) -> 81610.751
A33: LDO | B33: 0 | C33: 0 | D33: 0 | E33: 0 | F33: 0 | G33: 0 | H33: 0 | I33: 0 | J33: 0 | K33: 0 | L33: 0 | M33: 0 | N33: =SUM(B33:M33) -> 0
A34: LOBS/ Lube Oil | B34: 0 | C34: 9.7045232 | D34: 13.62142 | E34: 15.44879 | F34: 6.22 | G34: 7.17 | H34: 6.65 | I34: 6.17 | J34: 5.23 | K34: 5.22 | L34: 7.36 | M34: 10.15 | N34: =SUM(B34:M34) -> 92.944733
A35: Fuel Oil | B35: 154.63447 | C35: 290.60065 | D35: 259.84519 | E35: 91.294307 | F35: 0 | G35: 32.890422 | H35: 143.02356 | I35: 51.316551 | J35: 113.39127 | K35: 286.71381 | L35: 235.76861 | M35: 658.88088 | N35: =SUM(B35:M35) -> 2318.3597
A36: Bitumen | B36: 0 | C36: 0 | D36: 0 | E36: 0 | F36: 0 | G36: 6.6969465 | H36: 6.1853821 | I36: 0.1906253 | J36: 8.0361574 | K36: 0.3243114 | L36: 0.1052075 | M36: 1.9467151 | N36: =SUM(B36:M36) -> 23.485345
A37: Petcoke / CBFS | B37: 27.651771 | C37: 81.679647 | D37: 146.39033 | E37: 22.755858 | F37: 3.502018 | G37: 2.8089627 | H37: 0.32922005 | I37: 0.61548763 | J37: 0.99015475 | K37: 2.2542704 | L37: 2.4003687 | M37: 0.7533307 | N37: =SUM(B37:M37) -> 292.13142
A38: Others% | B38: 558.6194 | C38: 1023.0439 | D38: 492.28351 | E38: 444.88531 | F38: 512.44782 | G38: 546.39324 | H38: 377.23995 | I38: 333.47898 | J38: 298.95638 | K38: 464.54155 | L38: 331.86515 | M38: 1051.9455 | N38: =SUM(B38:M38) -> 6435.7007
A39: TOTAL PRODUCT EXPORT | B39: =SUM(B27:B38) -> 9004.7009 | C39: =SUM(C27:C38) -> 9725.8009 | D39: =SUM(D27:D38) -> 10736.057 | E39: =SUM(E27:E38) -> 11018.916 | F39: =SUM(F27:F38) -> 13378.269 | G39: =SUM(G27:G38) -> 12553.761 | H39: =SUM(H27:H38) -> 9888.0426 | I39: =SUM(I27:I38) -> 11060.239 | ... N39: =SUM(N27:N38) -> 157167.71
A40: NET IMPORT | B40: =+B25-B39 -> 19767.227 | C40: =+C25-C39 -> 14495.887 | D40: =+D25-D39 -> 20635.229 | E40: =+E25-E39 -> 25987.174 | F40: =+F25-F39 -> 34340.518 | G40: =+G25-G39 -> 29350.218 | H40: =+H25-H39 -> 30977.283 | I40: =+I25-I39 -> 38708.114 | ... N40: =+N25-N39 -> 412040.52
A41: Source: Oil Companies & DGCIS P= Provisional
A42: Notes:
A43: RIL SEZ imports/exports included in country's import/export data
A44: ^LNG import not included
...

Sheet PT_Import_Val_2019-20
E4: Petroleum Planning & Analysis Cell
A6: 2019-20
A7: (` Crore)
A8: Import/Export of Crude oil and Petroleum Products
A9: IMPORT/EXPORT | B9: APRIL | C9: MAY | D9: JUNE | E9: JULY | F9: AUGUST | G9: SEPTEMBER | H9: OCTOBER | I9: NOVEMBER | J9: DECEMBER | K9: JANUARY | L9: FEBRUARY | M9: MARCH | N9: TOTAL
A10: IMPORT^
A11: CRUDE OIL | B11: 67513.657 | C11: 66391.616 | D11: 55094.71 | E11: 62690.275 | F11: 62338.084 | G11: 52955.35 | H11: 59815.41 | I11: 61260.06 | J11: 62309.013 | K11: 68082.735 | L11: 55633.007 | M11: 42917.058 | N11: =SUM(B11:M11) -> 717000.98
A12: PRODUCTS
A13: LPG | B13: 4769.7727 | C13: 3904.5131 | D13: 3089.9555 | E13: 2316.0579 | F13: 3239.6886 | G13: 4280.9287 | H13: 4476.9438 | I13: 4389.4904 | J13: 4178.3815 | K13: 6001.0039 | L13: 5380.74 | M13: 4319.9766 | N13: =SUM(B13:M13) -> 50347.453
A14: MS | B14: 597.85531 | C14: 583.66173 | D14: 781.73439 | E14: 1118.5332 | F14: 745.74566 | G14: 1864.5318 | H14: 865.70233 | I14: 627.48763 | J14: 1060.0784 | K14: 889.65238 | L14: 255.56609 | M14: 219.48775 | N14: =SUM(B14:M14) -> 9610.0367
A15: Naphtha | B15: 516.47103 | C15: 555.41772 | D15: 272.19264 | E15: 764.86234 | F15: 752.74793 | G15: 977.8052 | H15: 471.67174 | I15: 394.59651 | J15: 580.10699 | K15: 798.87666 | L15: 269.51891 | M15: 323.46003 | N15: =SUM(B15:M15) -> 6677.7277
A16: ATF | B16: 308.64976 | C16: 0 | D16: 0 | E16: 0 | F16: 0.0046871 | G16: 0 | H16: 0 | I16: 0 | J16: 0.0002503 | K16: 0 | L16: 0 | M16: 0 | N16: =SUM(B16:M16) -> 308.65469
A17: SKO | B17: 0 | C17: 0 | D17: 0 | E17: 0 | F17: 0 | G17: 0 | H17: 0 | I17: 0 | J17: 0 | K17: 0 | L17: 0 | M17: 0 | N17: =SUM(B17:M17) -> 0
A18: HSD | B18: 604.48231 | C18: 817.87734 | D18: 1775.534 | E18: 486.38145 | F18: 197.04745 | G18: 592.59036 | H18: 278.21554 | I18: 50.677234 | J18: 2292.2289 | K18: 3035.0355 | L18: 1070.3524 | M18: 418.62693 | N18: =SUM(B18:M18) -> 11619.049
A19: LOBS/ Lube oil | B19: 881.33137 | C19: 1326.0387 | D19: 1188.1615 | E19: 1046.8374 | F19: 1033.1028 | G19: 885.75781 | H19: 1038.3793 | I19: 807.39512 | J19: 788.12116 | K19: 960.45859 | L19: 980.25181 | M19: 932.90852 | N19: =SUM(B19:M19) -> 11868.744
A20: Fuel Oil | B20: 111.27334 | C20: 287.10304 | D20: 925.8393 | E20: 429.63721 | F20: 814.80331 | G20: 1202.4481 | H20: 742.10673 | I20: 624.43503 | J20: 1501.8713 | K20: 2264.2628 | L20: 1248.8811 | M20: 1638.7794 | N20: =SUM(B20:M20) -> 11791.441
A21: Bitumen | B21: 264.95648 | C21: 306.8215 | D21: 290.13772 | E21: 210.69383 | F21: 121.87328 | G21: 154.23904 | H21: 282.18787 | I21: 284.48569 | J21: 335.8476 | K21: 430.06188 | L21: 517.80129 | M21: 434.53512 | N21: =SUM(B21:M21) -> 3633.6413
A22: Others& | B22: 2093.7864 | C22: 2627.7944 | D22: 2285.8894 | E22: 1799.7161 | F22: 1543.3424 | G22: 1533.0798 | H22: 1893.6425 | I22: 1306.591 | J22: 1546.9334 | K22: 1155.1963 | L22: 1063.3128 | M22: 1035.556 | N22: =SUM(B22:M22) -> 19884.841
A23: PRODUCT IMPORT* | B23: =SUM(B13:B22) -> 10148.579 | C23: =SUM(C13:C22) -> 10409.228 | D23: =SUM(D13:D22) -> 10609.444 | E23: =SUM(E13:E22) -> 8172.7194 | F23: =SUM(F13:F22) -> 8448.3561 | G23: =SUM(G13:G22) -> 11491.381 | H23: =SUM(H13:H22) -> 10048.85 | I23: =SUM(I13:I22) -> 8485.1586 | ... N23: =SUM(N13:N22) -> 125741.59
A24: TOTAL IMPORT | B24: =+B23+B11 -> 77662.236 | C24: =+C23+C11 -> 76800.843 | D24: =+D23+D11 -> 65704.155 | E24: =+E23+E11 -> 70862.994 | F24: =+F23+F11 -> 70786.44 | G24: =+G11+G23 -> 64446.73 | H24: =+H11+H23 -> 69864.26 | I24: =+I11+I23 -> 69745.218 | J24: =+J11+J23 -> 74592.582 | K24: =+K11+K23 -> 83617.283 | L24: =+L11+L23 -> 66419.432 | M24: =+M11+M23 -> 52240.389 | N24: =+N11+N23 -> 842742.56
A25: PRODUCT EXPORT @
A26: LPG | B26: 174.88275 | C26: 168.9649 | D26: 161.15363 | E26: 147.57696 | F26: 103.63082 | G26: 135.87477 | H26: 128.74114 | I26: 169.54761 | J26: 174.0389 | K26: 167.48977 | L26: 217.56204 | M26: 220.99023 | N26: =SUM(B26:M26) -> 1970.4535
A27: MS! | B27: 4999.8536 | C27: 6508.5983 | D27: 3494.7136 | E27: 5087.2176 | F27: 3765.7303 | G27: 5158.6524 | H27: 4304.1542 | I27: 4564.351 | J27: 6138.7151 | K27: 3562.1121 | L27: 4260.2659 | M27: 2667.4995 | N27: =SUM(B27:M27) -> 54511.864
A28: Naphtha$ | B28: 2453.6156 | C28: 3729.782 | D28: 1815.4589 | E28: 1387.5574 | F28: 2201.9512 | G28: 2666.7331 | H28: 3165.2473 | I28: 2823.3627 | J28: 3931.022 | K28: 3156.0918 | L28: 2464.4659 | M28: 1713.261 | N28: =SUM(B28:M28) -> 31508.549
A29: ATF# | B29: 2484.4869 | C29: 2129.9328 | D29: 2623.3305 | E29: 2043.254 | F29: 2276.2496 | G29: 3124.5279 | H29: 2604.0096 | I29: 2995.4611 | J29: 2835.4144 | K29: 2105.8387 | L29: 1930.0485 | M29: 1305.7169 | N29: =SUM(B29:M29) -> 28458.271
A30: SKO | B30: 8.1339013 | C30: 8.1023231 | D30: 10.045218 | E30: 8.1984372 | F30: 10.428487 | G30: 10.821107 | H30: 4.6546983 | I30: 8.7533441 | J30: 83.648421 | K30: 222.34123 | L30: 69.739898 | M30: 114.83362 | N30: =SUM(B30:M30) -> 559.70069
A31: HSD | B31: 8771.2941 | C31: 9143.3096 | D31: 8744.3096 | E31: 10609.285 | F31: 9452.2034 | G31: 13679.85 | H31: 12534.041 | I31: 13264.075 | J31: 13113.095 | K31: 8781.8916 | L31: 8499.7449 | M31: 7326.1721 | N31: =SUM(B31:M31) -> 123919.27
A32: LDO | B32: 0 | C32: 0 | D32: 0 | E32: 0 | F32: 0 | G32: 0 | H32: 0 | I32: 0 | J32: 0 | K32: 0 | L32: 0 | M32: 0 | N32: =SUM(B32:M32) -> 0
A33: LOBS/ Lube Oil | B33: 0.87 | C33: 5.91 | D33: 9.69 | E33: 9.9 | F33: 8.57 | G33: 10.61 | H33: 8.6 | I33: 10.39 | J33: 7.54 | K33: 8.56 | L33: 10.15 | M33: 5.18 | N33: =SUM(B33:M33) -> 95.97
A34: Fuel Oil | B34: 160.51994 | C34: 280.11 | D34: 315.68453 | E34: 425.9154 | F34: 371.47372 | G34: 979.87083 | H34: 329.32122 | I34: 330.48937 | J34: 66.622912 | K34: 0.3254741 | L34: 336.23655 | M34: 214.64686 | N34: =SUM(B34:M34) -> 3811.2168
A35: Bitumen | B35: 12.361681 | C35: 11.324626 | D35: 2.4015566 | E35: 2.9478871 | F35: 15.044569 | G35: 7.0681826 | H35: 7.7166939 | I35: 7.8224159 | J35: 0 | K35: 14.448027 | L35: 7.4645774 | M35: 0 | N35: =SUM(B35:M35) -> 88.600216
A36: Others% | B36: 398.41287 | C36: 935.21856 | D36: 525.40428 | E36: 891.08529 | F36: 1474.1757 | G36: 582.93106 | H36: 504.01173 | I36: 690.8501 | J36: 824.78967 | K36: 877.82389 | L36: 750.52526 | M36: 638.41912 | N36: =SUM(B36:M36) -> 9093.6475
A37: TOTAL PRODUCT EXPORT | B37: =SUM(B26:B36) -> 19464.431 | C37: =SUM(C26:C36) -> 22921.253 | D37: =SUM(D26:D36) -> 17702.192 | E37: =SUM(E26:E36) -> 20612.938 | F37: =SUM(F26:F36) -> 19679.458 | G37: =SUM(G26:G36) -> 26356.939 | H37: =SUM(H26:H36) -> 23590.498 | I37: =SUM(I26:I36) -> 24865.102 | ... N37: =SUM(N26:N36) -> 254017.54
A38: NET IMPORT | B38: =+B24-B37 -> 58197.805 | C38: =+C24-C37 -> 53879.59 | D38: =+D24-D37 -> 48001.963 | E38: =+E24-E37 -> 50250.057 | F38: =+F24-F37 -> 51106.982 | G38: =+G24-G37 -> 38089.791 | H38: =+H24-H37 -> 46273.763 | I38: =+I24-I37 -> 44880.116 | ... N38: =+N24-N37 -> 588725.02
A39: Source: Oil Companies & DGCIS P= Provisional
A40: Notes:
A41: RIL SEZ imports/exports included in country's import/export data
A42: ^LNG import not included
A43: & Others in import include Petcoke, Paraffin wax, Petroleum Jelly, Aviation Gas, MTBE, Reformate etc.
A44: @ Nepal sales by IOCL, Nepal and Bhutan sales by BPCL are considered in total exports with average Rupee-US$ exchange rate
...

Sheet PT_Import_Val_2018-19
E4: Petroleum Planning & Analysis Cell
A6: 2018-19
A7: (` Crore)
A8: Import/Export of Crude oil and Petroleum Products
A9: IMPORT/EXPORT | B9: APRIL | C9: MAY | D9: JUNE | E9: JULY | F9: AUGUST | G9: SEPTEMBER | H9: OCTOBER | I9: NOVEMBER | J9: DECEMBER | K9: JANUARY | L9: FEBRUARY | M9: MARCH | N9: TOTAL
A10: IMPORT^
A11: CRUDE OIL$ | B11: 54773.944 | C11: 68799.381 | D11: 69745.59 | E11: 71013.142 | F11: 69055.323 | G11: 70493.004 | H11: 84901.828 | I11: 59275.17 | J11: 59454.511 | K11: 58810.762 | L11: 54282.3 | M11: 62577.894 | N11: =SUM(B11:M11) -> 783182.85
A12: PRODUCTS
A13: LPG | B13: 2757.0098 | C13: 3035.2064 | D13: 4267.9005 | E13: 4310.9199 | F13: 5131.2612 | G13: 5237.1664 | H13: 4842.8698 | I13: 4134.2692 | J13: 3868.2433 | K13: 3279.6501 | L13: 4070.0182 | M13: 5004.5281 | N13: =SUM(B13:M13) -> 49939.043
A14: MS | B14: 0 | C14: 862.97443 | D14: 0 | E14: 0 | F14: 193.91638 | G14: 244.3861 | H14: 194.87476 | I14: 155.44097 | J14: 131.01597 | K14: 249.29843 | L14: 414.40872 | M14: 657.61487 | N14: =SUM(B14:M14) -> 3103.9306
A15: Naphtha | B15: 1353.4022 | C15: 588.1532 | D15: 977.16449 | E15: 783.83422 | F15: 761.58519 | G15: 821.18994 | H15: 1346.7676 | I15: 1166.5784 | J15: 703.54944 | K15: 196.43652 | L15: 668.14112 | M15: 298.5749 | N15: =SUM(B15:M15) -> 9665.3772
A16: ATF | B16: 176.71896 | C16: 34.988455 | D16: 76.298114 | E16: 157.36638 | F16: 199.07779 | G16: 208.87398 | H16: 249.32187 | I16: 114.69872 | J16: 126.2723 | K16: 23.671521 | L16: 0 | M16: 25.174772 | N16: =SUM(B16:M16) -> 1392.4629
A17: SKO | B17: 0 | C17: 0 | D17: 0 | E17: 0 | F17: 0 | G17: 0 | H17: 0 | I17: 0 | J17: 0 | K17: 0 | L17: 0 | M17: 0 | N17: =SUM(B17:M17) -> 0
A18: HSD | B18: 295.53598 | C18: 545.76658 | D18: 29.937407 | E18: 11.300313 | F18: 20.15001 | G18: 13.501665 | H18: 112.01791 | I18: 46.399008 | J18: 34.026876 | K18: 301.8214 | L18: 740.36327 | M18: 334.94553 | N18: =SUM(B18:M18) -> 2485.7659
A19: LOBS/ Lube oil | B19: 608.61119 | C19: 1117.6558 | D19: 1229.4522 | E19: 1053.9011 | F19: 1232.448 | G19: 942.87353 | H19: 1425.1504 | I19: 1223.8616 | J19: 1103.0901 | K19: 1049.0552 | L19: 945.25292 | M19: 1417.8946 | N19: =SUM(B19:M19) -> 13349.247
A20: Fuel Oil | B20: 930.81036 | C20: 405.34682 | D20: 703.1081 | E20: 596.54779 | F20: 264.05185 | G20: 201.68006 | H20: 191.48566 | I20: 132.85493 | J20: 655.19846 | K20: 65.601048 | L20: 399.33325 | M20: 235.85536 | N20: =SUM(B20:M20) -> 4781.8737
A21: Bitumen | B21: 228.02167 | C21: 201.17625 | D21: 129.29773 | E21: 107.08283 | F21: 91.379912 | G21: 142.17175 | H21: 160.02713 | I21: 173.54262 | J21: 170.83772 | K21: 209.16619 | L21: 204.59119 | M21: 332.17981 | N21: =SUM(B21:M21) -> 2149.4748
A22: Others& | B22: 2021.5809 | C22: 2052.486 | D22: 2411.7698 | E22: 2445.6007 | F22: 2353.9809 | G22: 1908.5649 | H22: 1661.8702 | I22: 1892.2509 | J22: 2764.0375 | K22: 2564.0837 | L22: 2439.5475 | M22: 2282.4895 | N22: =SUM(B22:M22) -> 26798.263
A23: PRODUCT IMPORT* | B23: =SUM(B13:B22) -> 8371.6911 | C23: =SUM(C13:C22) -> 8843.7539 | D23: =SUM(D13:D22) -> 9824.9284 | E23: =SUM(E13:E22) -> 9466.5532 | F23: =SUM(F13:F22) -> 10247.851 | G23: =SUM(G13:G22) -> 9720.4083 | H23: =SUM(H13:H22) -> 10184.385 | I23: =SUM(I13:I22) -> 9039.8964 | ... N23: =SUM(N13:N22) -> 113665.44
A24: TOTAL IMPORT | B24: =+B23+B11 -> 63145.635 | C24: =+C23+C11 -> 77643.135 | D24: =+D23+D11 -> 79570.519 | E24: =+E23+E11 -> 80479.695 | F24: =+F23+F11 -> 79303.174 | G24: =+G11+G23 -> 80213.413 | H24: =+H11+H23 -> 95086.214 | I24: =+I11+I23 -> 68315.066 | J24: =+J11+J23 -> 69010.783 | K24: =+K11+K23 -> 66749.546 | L24: =+L11+L23 -> 64163.956 | M24: =+M11+M23 -> 73167.151 | N24: =+N11+N23 -> 896848.29
A25: PRODUCT EXPORT @
A26: LPG | B26: 119.7943 | C26: 137.08898 | D26: 151.5572 | E26: 162.47859 | F26: 158.74388 | G26: 173.27279 | H26: 192.81618 | I26: 173.88593 | J26: 209.2206 | K26: 172.88718 | L26: 145.64079 | M26: 178.35069 | N26: =SUM(B26:M26) -> 1975.7371
A27: MS! | B27: 4192.1922 | C27: 5836.4644 | D27: 5930.7688 | E27: 5225.7965 | F27: 4276.5388 | G27: 6355.689 | H27: 6397.8962 | I27: 4683.245 | J27: 3971.7044 | K27: 4013.4746 | L27: 4057.9005 | M27: 5477.1386 | N27: =SUM(B27:M27) -> 60418.809
A28: Naphtha$ | B28: 2063.5679 | C28: 2427.2591 | D28: 2767.7536 | E28: 2777.4232 | F28: 3059.5256 | G28: 3720.6767 | H28: 2771.8231 | I28: 2538.2831 | J28: 2010.6125 | K28: 1489.9123 | L28: 1535.6898 | M28: 1730.5942 | N28: =SUM(B28:M28) -> 28893.121
A29: ATF# | B29: 2153.5471 | C29: 2595.3935 | D29: 3420.2001 | E29: 3089.686 | F29: 2914.0127 | G29: 3348.2525 | H29: 3274.5213 | I29: 2923.2248 | J29: 2537.261 | K29: 2399.6222 | L29: 2118.4889 | M29: 3255.7852 | N29: =SUM(B29:M29) -> 34029.995
A30: SKO | B30: 6.0975412 | C30: 8.7787065 | D30: 9.3953493 | E30: 8.2056697 | F30: 9.4184028 | G30: 7.9145972 | H30: 10.031256 | I30: 8.4089086 | J30: 7.70049 | K30: 6.9460234 | L30: 7.1694645 | M30: 7.5735677 | N30: =SUM(B30:M30) -> 97.639977
A31: HSD | B31: 6433.9965 | C31: 8960.3749 | D31: 10802.442 | E31: 10941.49 | F31: 12955.968 | G31: 14046.101 | H31: 14534.119 | I31: 10435.924 | J31: 8446.6275 | K31: 6941.0232 | L31: 7924.0228 | M31: 11096.536 | N31: =SUM(B31:M31) -> 123518.62
A32: LDO | B32: 0 | C32: 0 | D32: 0 | E32: 0 | F32: 0 | G32: 0 | H32: 131.6361 | I32: 232.19735 | J32: 0 | K32: 0 | L32: 0 | M32: 0 | N32: =SUM(B32:M32) -> 363.83345
A33: LOBS/ Lube Oil | B33: 2.88 | C33: 5.56 | D33: 8.86 | E33: 7.22 | F33: 9.46 | G33: 10.92 | H33: 6.42 | I33: 8.85 | J33: 10.54 | K33: 8.37 | L33: 8.41 | M33: 18.51 | N33: =SUM(B33:M33) -> 106
A34: Fuel Oil | B34: 40.42641 | C34: 98.245335 | D34: 218.73405 | E34: 583.69461 | F34: 1029.8589 | G34: 1032.9622 | H34: 1124.7485 | I34: 242.61502 | J34: 993.80293 | K34: 681.24494 | L34: 217.22634 | M34: 273.54807 | N34: =SUM(B34:M34) -> 6537.1073
A35: Bitumen | B35: 0 | C35: 1.1405297 | D35: 9.2947649 | E35: 0 | F35: 6.515428 | G35: 15.921297 | H35: 7.4231193 | I35: 0.3021494 | J35: 14.517575 | K35: 0 | L35: 15.304851 | M35: 1.3777244 | N35: =SUM(B35:M35) -> 71.797439
A36: Others% | B36: 1012.822 | C36: 1025.3973 | D36: 786.4053 | E36: 1097.3939 | F36: 1067.9525 | G36: 999.03696 | H36: 1137.8397 | I36: 996.17934 | J36: 745.18867 | K36: 966.34049 | L36: 831.78928 | M36: 1017.5137 | N36: =SUM(B36:M36) -> 11683.859
A37: TOTAL PRODUCT EXPORT | B37: =SUM(B26:B36) -> 16025.324 | C37: =SUM(C26:C36) -> 21095.703 | D37: =SUM(D26:D36) -> 24105.411 | E37: =SUM(E26:E36) -> 23893.389 | F37: =SUM(F26:F36) -> 25487.994 | G37: =SUM(G26:G36) -> 29710.747 | H37: =SUM(H26:H36) -> 29589.274 | I37: =SUM(I26:I36) -> 22243.116 | ... N37: =SUM(N26:N36) -> 267696.52
A38: NET IMPORT | B38: =+B24-B37 -> 47120.311 | C38: =+C24-C37 -> 56547.432 | D38: =+D24-D37 -> 55465.108 | E38: =+E24-E37 -> 56586.306 | F38: =+F24-F37 -> 53815.18 | G38: =+G24-G37 -> 50502.666 | H38: =+H24-H37 -> 65496.939 | I38: =+I24-I37 -> 46071.951 | ... N38: =+N24-N37 -> 629151.76
A39: Source : Oil Companies & DGCIS, (P) : Provisional
A40: Notes:
A41: RIL SEZ imports/exports included in country's import/export data
A42: ^LNG import not included
A43: & Others in import include Petcoke, Paraffin wax, Petroleum Jelly, Aviation Gas, MTBE, Reformate etc.
A44: @ Nepal sales by IOCL, Nepal and Bhutan sales by BPCL are considered in total exports with average Rupee-US$ exchange rate
...

Sheet PT_Import_Val_2017-18
G3: Petroleum Planning & Analysis Cell
C5: 2017-18
C6: (` Crore)
C7: Import/Export of Crude oil and Petroleum Products
C8: IMPORT/EXPORT | D8: APRIL | E8: MAY | F8: JUNE | G8: JULY | H8: AUGUST | I8: SEPTEMBER | J8: OCTOBER | K8: NOVEMBER | L8: DECEMBER | M8: JANUARY | N8: FEBRUARY | O8: MARCH | P8: TOTAL
C9: IMPORT^
C10: CRUDE OIL | D10: 43210.211 | E10: 40654.238 | F10: 37459.893 | G10: 37276.692 | H10: 41046.648 | I10: 42201.241 | J10: 48763.242 | K10: 52708.99 | L10: 54759.746 | M10: 61776.803 | N10: 52197.992 | O10: 54394.453 | P10: =SUM(D10:O10) -> 566450.15
C11: PRODUCTS
C12: LPG | D12: 2853.1998 | E12: 2039.8628 | F12: 1634.1871 | G12: 2272.8733 | H12: 3256.0526 | I12: 2865.7339 | J12: 4661.7289 | K12: 4749.4081 | L12: 4368.5272 | M12: 3735.5489 | N12: 2501.0255 | O12: 2937.0491 | P12: =SUM(D12:O12) -> 37875.197
C13: MS | D13: 0 | E13: 0 | F13: 116.92154 | G13: 464.57654 | H13: 0 | I13: 0 | J13: 0 | K13: 0 | L13: 0 | M13: 0 | N13: 0 | O13: 0 | P13: =SUM(D13:O13) -> 581.49809
C14: Naphtha | D14: 269.54218 | E14: 327.74434 | F14: 228.49728 | G14: 501.56809 | H14: 605.86008 | I14: 605.87458 | J14: 821.97462 | K14: 431.4241 | L14: 745.44747 | M14: 1484.1951 | N14: 1179.5432 | O14: 959.5414 | P14: =SUM(D14:O14) -> 8161.2125
C15: ATF | D15: 104.7956 | E15: 85.507218 | F15: 89.035503 | G15: 74.866421 | H15: 86.518391 | I15: 91.594227 | J15: 102.34362 | K15: 139.76068 | L15: 53.242719 | M15: 146.19379 | N15: 54.539577 | O15: 130.91441 | P15: =SUM(D15:O15) -> 1159.3122
C16: SKO | D16: 0 | E16: 0 | F16: 0 | G16: 0 | H16: 0 | I16: 0 | J16: 0 | K16: 0 | L16: 0 | M16: 0 | N16: 0 | O16: 0 | P16: =SUM(D16:O16) -> 0
C17: HSD | D17: 59.174278 | E17: 1393.9209 | F17: 1342.5557 | G17: 951.29559 | H17: 36.906523 | I17: 5.674142 | J17: 12.858037 | K17: 62.539633 | L17: 28.839918 | M17: 44.505849 | N17: 31.615361 | O17: 298.87125 | P17: =SUM(D17:O17) -> 4268.7572
C18: LOBS/ Lube oil | D18: 919.91443 | E18: 847.06065 | F18: 902.57677 | G18: 805.71815 | H18: 630.80441 | I18: 885.73359 | J18: 1006.7066 | K18: 1033.971 | L18: 1045.2783 | M18: 1178.2383 | N18: 1510.276 | O18: 1308.3616 | P18: =SUM(D18:O18) -> 12074.64
C19: Fuel Oil | D19: 197.39466 | E19: 359.31263 | F19: 112.55488 | G19: 211.74062 | H19: 94.765671 | I19: 140.76355 | J19: 323.41302 | K19: 267.76628 | L19: 176.62737 | M19: 303.93725 | N19: 432.34465 | O19: 610.83379 | P19: =SUM(D19:O19) -> 3231.4544
C20: Bitumen | D20: 146.13131 | E20: 229.08952 | F20: 75.834159 | G20: 44.584066 | H20: 88.942724 | I20: 105.79823 | J20: 117.82251 | K20: 135.81767 | L20: 228.97251 | M20: 199.59371 | N20: 275.44853 | O20: 254.23911 | P20: =SUM(D20:O20) -> 1902.2741
C21: Others | D21: 1280.7619 | E21: 1389.6902 | F21: 1602.2615 | G21: 1721.7269 | H21: 1874.3048 | I21: 934.17483 | J21: 1773.1594 | K21: 1124.7181 | L21: 2124.0534 | M21: 1828.3839 | N21: 1273.0731 | O21: 2193.2654 | P21: =SUM(D21:O21) -> 19119.573
C22: PRODUCT IMPORT* | D22: =SUM(D12:D21) -> 5830.9142 | E22: =SUM(E12:E21) -> 6672.1882 | F22: =SUM(F12:F21) -> 6104.4244 | G22: =SUM(G12:G21) -> 7048.9496 | H22: =SUM(H12:H21) -> 6674.1552 | I22: =SUM(I12:I21) -> 5635.347 | J22: =SUM(J12:J21) -> 8820.0068 | K22: =SUM(K12:K21) -> 7945.4055 | ... P22: =SUM(P12:P21) -> 88373.919
